<mujoco model="initial_humanoid">
  
  <option gravity="0 0 -9.81">
    
    <flag sensornoise="enable" />
  </option>

  
  <visual>
    <map zfar="30" />
    
    <rgba haze="0.15 0.25 0.35 1" />
    
    
  </visual>

  
  <statistic center="0 0 0.7" />

  
  <asset>
    
    <texture type="skybox" builtin="gradient" rgb1=".3 .5 .7" rgb2="0 0 0" width="32" height="512" />

    
    <texture name="body" type="cube" builtin="flat" mark="cross" width="128" height="128" rgb1="0.8 0.6 0.4" rgb2="0.8 0.6 0.4" markrgb="1 1 1" random="0.01" />
    <material name="body" texture="body" texuniform="true" rgba="0.8 0.6 .4 1" />

    
    <texture name="grid" type="2d" builtin="checker" width="512" height="512" rgb1=".1 .2 .3" rgb2=".2 .3 .4" />
    <material name="grid" texture="grid" texrepeat="1 1" texuniform="true" reflectance=".2" />

    
    <mesh name="foot_mesh" vertex="-0.13528 -0.035 0   -0.13528 0.035 0   0.13528 -0.035 0   0.13528 0.035 0  0 -0.035 0.06942 0 0.035 0.06942" />
  </asset>

  
  <default>

    <default class="body">

      
      
      <geom type="capsule" mass="10" condim="1" friction="0.7 0.005 0.0001" solimp=".9 .99 .003" solref=".015 1" material="body" group="1" />
      
      
      <default class="shin">
        <geom fromto="0 0 0.1 0 0 0" size="0.025" />
      </default>

    </default>
  </default>

    
	<worldbody>
      
      <geom name="ground" size="0 0 .05" type="plane" material="grid" condim="3" friction="0.99 0.99 0.99" solimp=".9 .99 .003" solref=".015 1" />
      
      
      <light name="spotlight" mode="targetbodycom" target="foot" diffuse=".8 .8 .8" specular="0.3 0.3 0.3" pos="0 -6 4" cutoff="30" />
    
        
        <body name="foot" pos="0 0 0.00">
          
      
          
          <joint name="rotation_dof" type="hinge" axis="0 -1 0" pos="-0.27056 0 0.035" />
          <joint type="slide" name="joint_slide_x" axis="-1 0 0" pos="0.13528 0 0.035" />
          <joint type="slide" name="joint_slide_z" axis="0 0 1" pos="0.13528 0 0.035" />
  
          <geom type="mesh" mesh="foot_mesh" name="foot_geom" solref=".015 1" solimp=".9 .99 .003" rgba="0.8 0.6 .4 0" />
          
          <site name="front_foot_force_sensor_site" type="cylinder" size="0.075" rgba="0.5 0.5 0.5 1" fromto="-0.13528 0 0.0 -0.13528 0 0.1" />
          <site name="back_foot_force_sensor_site" type="cylinder" size="0.075" rgba="0.5 0.5 0.5 1" fromto="0.13528 0 0.0 0.13528 0 0.1" />

          <site name="front_foot_site" pos="-0.09018666666666668 0 0.025" size="0.01 0.01 0.01" />
          <site name="back_foot_site" pos="0.09018666666666668 0 0.025" size="0.01 0.01 0.01" />
          
          <body name="shin_body" pos="0 0 0.06942">
          
            
          
          
            <joint type="hinge" name="ankle_hinge" axis="0 -1 0" damping="1" pos="0 0 0" />
            <geom name="shin_geom" class="shin" mass="0" fromto="0 0 1.78 0 0 0" />
            <geom name="m_body" type="sphere" size="0.05" pos="0 0 1.0234999999999999" mass="77.68" />
            <site name="front_shin_site" pos="-0.01 0 0.34709999999999996" size="0.01 0.01 0.01" />
            <site name="back_shin_site" pos="0.01 0 0.34709999999999996" size="0.01 0.01 0.01" />

          </body>

        </body>
      
      
	</worldbody>
	
  
  <tendon>
    <spatial name="front_tendon" limited="true" range="0.1 0.7" width="0.0025" springlength="-1" stiffness="1">
      <site site="front_foot_site" />
      <site site="front_shin_site" />
    </spatial>
  </tendon>

  <tendon>
    <spatial name="back_tendon" limited="true" range="0.1 0.7" width="0.0025" springlength="-1" stiffness="1">
      <site site="back_foot_site" />
      <site site="back_shin_site" />
    </spatial>
  </tendon>

  <contact>
    
    <pair name="foot_ground_friction" geom1="foot_geom" geom2="ground" solref="0.015 1" solimp="0.99 .99 .003" friction="0.9 0.9 0.99 0.9 0.9" />
    <pair name="longlink_ground_friction" geom1="shin_geom" geom2="ground" solref="0.015 1" solimp="0.99 .99 .003" friction=".99 .99 .99" />
  </contact>

    
	<actuator>
      <muscle name="front_muscle" tendon="front_tendon" force="1200" />
      <muscle name="back_muscle" tendon="back_tendon" force="1200" />
  </actuator>

    
	<sensor>
      <jointpos joint="ankle_hinge" />
      <touch site="front_foot_force_sensor_site" />
      <touch site="back_foot_force_sensor_site" />
	</sensor>

  

</mujoco>