<mujoco model="initial_humanoid">
  <!-- SET GRAVITY TO POINT DOWN -->
  <option gravity="0 0 -9.81">
    <!-- FLAG TO ADD NOISE TO SENSORS -->
    <flag sensornoise="enable"/>
  </option>

  <!-- VISUAL SETUP STUFF THAT I DON'T FULLY UNDERSTAND YET -->
  <visual>
    <map zfar="30"/>
    <!-- <scale forcewidth="0.1" contactwidth="0.1" contactheight="0.1" connect="0.1" com="0.4" selectpoint="0.2" jointlength="0.1" jointwidth="0.1" actuatorlength="0.7" actuatorwidth="0.2" framelength="1" framewidth="0.1"/> -->
    <rgba haze="0.15 0.25 0.35 1" />
    <!-- force="1 0.5 0.5 1" contactforce="0.7 0.9 0.9 1" com="0.9 0.9 0.9 1"/> -->
    <!-- <global offwidth="2560" offheight="1440" elevation="-20" azimuth="120"/> -->
  </visual>

  <!-- DON'T KNOW WHAT THIS DOES YET -->
  <statistic center="0 0 0.7"/>

  <!-- Set up default texture and material parameters for the bodies in the simulation and the ground in the simulation -->
  <asset>
    <!-- this makes the sky blue in the simulation: -->
    <texture type="skybox" builtin="gradient" rgb1=".3 .5 .7" rgb2="0 0 0" width="32" height="512"/>

    <!-- configure the texture and material of the default body created in a simulation -->
    <texture name="body" type="cube" builtin="flat" mark="cross" width="128" height="128" rgb1="0.8 0.6 0.4" rgb2="0.8 0.6 0.4" markrgb="1 1 1" random="0.01"/>
    <material name="body" texture="body" texuniform="true" rgba="0.8 0.6 .4 1"/>

    <!-- configure the default texture and material for the ground of the simulation -->
    <texture name="grid" type="2d" builtin="checker" width="512" height="512" rgb1=".1 .2 .3" rgb2=".2 .3 .4"/>
    <material name="grid" texture="grid" texrepeat="1 1" texuniform="true" reflectance=".2"/>

    <!-- create triangle mesh to represent foot -->
    <mesh name="foot_mesh" vertex="-1 0 0  -1 0 0  1 0 0  0 -1 0  0 1 0  0.25 0 0.5"/>
  </asset>

  <!-- SECTION TO DEFINE GEOMETRIES AND JOINTS -->
  <default>

    <default class="body">

      <!-- geoms -->
      <!-- ALL GEOMETRIES ARE CAPSULE TYPE -->
      <geom type="capsule" mass="10" condim="1" friction="0.7 0.005 0.0001" solimp=".9 .99 .003" solref=".015 1" material="body" group="1"/>
      
      <!-- SHIN GEOMETRY -->
      <default class="shin">
        <geom fromto="0 0 0.1 0 0 0" size = "0.025"/>
      </default>

    </default>
  </default>

    <!-- DEFINE THE LEG, STARTING FROM THE WORLDBODY FRAME? -->
	<worldbody>
      <!-- DEFINE THE FLOOR IN THE ENVIRONMENT -->
      <geom name="ground" size="0 0 .05" type="plane" material="grid" condim="3" friction='0.99 0.99 0.99' solimp=".9 .99 .003" solref=".015 1"/>
      
      <!-- LIGHT SETTING -->
      <light name="spotlight" mode="targetbodycom" target="foot" diffuse=".8 .8 .8" specular="0.3 0.3 0.3" pos="0 -6 4" cutoff="30"/>
    
        <!-- BODY FOR SHIN; CAN HAVE MAX 6-DOF -->
        <body name="foot" >
          <!-- <joint name="knee_right" class="knee"/> -->
      
          <!-- Create prismatic joints to constrain motion along the x and z directions -->
          <joint name="rotation_dof" type="hinge" axis="0 -1 0"/>
          <joint type="slide" name="joint_slide_x" axis="-1 0 0"/>
          <joint type="slide" name="joint_slide_z" axis="0 0 1"/>
  
          <geom type="mesh" mesh="foot_mesh" name="foot_geom" solref=".015 1" solimp=".9 .99 .003" rgba="0.8 0.6 .4 0"/>
          
          <site name="front_foot_force_sensor_site" type="cylinder" size="0.075" rgba="0.5 0.5 0.5 1"/>
          <site name="back_foot_force_sensor_site" type="cylinder" size="0.075" rgba="0.5 0.5 0.5 1"/>

          <site name="front_foot_site" pos="-0.5 0 0.25" size="0.01 0.01 0.01"/>
          <site name="back_foot_site" pos="0.5 0 0.25" size="0.01 0.01 0.01"/>
          
          <body name="shin_body">
          
            <!-- <inertial pos="0 0 0.5" mass="1"/>   -->
          
          <!-- Create a hinge joint to constrain rotation around the y-axis (normal to the x-z plane) -->
            <joint type="hinge" name="ankle_hinge" axis="0 -1 0" damping="1"/>
            <geom name="shin_geom" class="shin"/>
            <geom name="m_body" type="sphere" size="0.05" pos="0 0 0.75"/>
            <site name="front_shin_site" pos="-0.0125 0 0.5" size="0.01 0.01 0.01"/>
            <site name="back_shin_site" pos="0.0125 0 0.5" size="0.01 0.01 0.01"/>

          </body>

        </body>
      <!-- </body> -->
      <!-- END OF DEFINING THE LEG IN 3D SPACE -->
	</worldbody>
	
  <!-- Define the tendon -->
  <tendon>
    <spatial name="front_tendon" limited="true" range="0.1 0.7" width="0.0025" springlength="-1" stiffness="1">
      <site site="front_foot_site"/>
      <site site="front_shin_site"/>
    </spatial>
  </tendon>

  <tendon>
    <spatial name="back_tendon" limited="true" range="0.1 0.7" width="0.0025" springlength="-1" stiffness="1">
      <site site="back_foot_site"/>
      <site site="back_shin_site"/>
    </spatial>
  </tendon>

  <contact>
    <!-- <pair geom1="foot_geom" geom2="ground"/> -->
    <pair name="foot_ground_friction" geom1="foot_geom" geom2="ground" solref="0.015 1" solimp="0.99 .99 .003" friction=".99 .99 .99"/>
    <pair name="longlink_ground_friction" geom1="shin_geom" geom2="ground" solref="0.015 1" solimp="0.99 .99 .003" friction=".99 .99 .99"/>
  </contact>

    <!-- ACTUATORS FOR THE ANKLE JOINTS -->
	<actuator>
      <muscle name="front_muscle" tendon="front_tendon" force="1200"/>
      <muscle name="back_muscle" tendon="back_tendon" force="1200"/>
  </actuator>

    <!-- SENSORS FOR THE ANKLE JOINTS -->
	<sensor>
      <jointpos joint='ankle_hinge'/>
      <touch site='front_foot_force_sensor_site'/>
      <touch site='back_foot_force_sensor_site'/>
	</sensor>

  

</mujoco>