<mujoco model="Leg">
  
  <option gravity="0 0 -9.81">
    
    <flag sensornoise="enable" />
  </option>

  
  <visual>
    <map force="0.1" zfar="30" />
    <rgba haze="0.15 0.25 0.35 1" />
    <global offwidth="2560" offheight="1440" elevation="-20" azimuth="120" />
  </visual>

  
  <statistic center="0 0 0.7" />

  
  <asset>
    <texture type="skybox" builtin="gradient" rgb1=".3 .5 .7" rgb2="0 0 0" width="32" height="512" />
    <texture name="body" type="cube" builtin="flat" mark="cross" width="128" height="128" rgb1="0.8 0.6 0.4" rgb2="0.8 0.6 0.4" markrgb="1 1 1" random="0.01" />
    <material name="body" texture="body" texuniform="true" rgba="0.8 0.6 .4 1" />
    <texture name="grid" type="2d" builtin="checker" width="512" height="512" rgb1=".1 .2 .3" rgb2=".2 .3 .4" />
    <material name="grid" texture="grid" texrepeat="1 1" texuniform="true" reflectance=".2" />
  </asset>

  
  <default>
    <motor ctrlrange="-1 1" ctrllimited="true" />
    <default class="body">

      
      
      <geom type="capsule" mass="10" condim="1" friction=".7" solimp=".9 .99 .003" solref=".015 1" material="body" group="1" />
      
      
      <default class="shin">
        <geom fromto="0 0 0 0 0 -.3" size=".045" />
      </default>


      
      <default class="foot">
        <geom type="capsule" size=".035" friction="1 0 0" mass="2" />
        
        <default class="foot1">
          <geom fromto="-.07 0 0 .14 0 0" />
        </default>
        
        <default class="foot2">
          <geom fromto="-.07 .02 0 .14 .02 0" />
        </default>
       </default>

      
      
      <default class="knee">
        <joint type="hinge" pos="0 0 .02" range="-160 160" />
      </default>
      
      <joint type="hinge" damping=".2" stiffness="1" armature=".01" limited="true" solimplimit="0 .99 .01" />
      <default class="ankle">
        <joint range="-50 50" />
        
        
        <default class="ankle_y">
          <joint pos="0 0 .04" axis="0 1 0" stiffness="6" />
        </default>
        
        
        <default class="ankle_x">
          <joint pos="0 0 .04" stiffness="3" />
        </default>
      </default>  

    </default>
  </default>

    
	<worldbody>
      
      <geom name="floor" size="0 0 .05" type="plane" material="grid" condim="3" friction="1 0 0" />
      
      
      <light name="spotlight" mode="targetbodycom" target="shin_right" diffuse=".8 .8 .8" specular="0.3 0.3 0.3" pos="0 -6 4" cutoff="30" />
      
      
        
        
        
        <body name="shin_right" pos="0 0 2">
          
          <geom name="shin_geom" class="shin" fromto="0 0 0 0 0 -1.78" mass="77.68" />

          
          <joint type="hinge" name="joint_hinge" axis="0 1 0" />
      
          
          <joint type="slide" name="joint_slide_x" axis="1 0 0" />
          <joint type="slide" name="joint_slide_z" axis="0 0 1" />
    

          
          <body name="le_foot" pos="-0.051406400000000005 0 -1.8">
            
            
            <joint name="ankle_y_right" class="ankle_y" />
            
            <geom name="foot1_right" class="foot2" fromto="0 .02 0 0.27056 .02 0" mass="2.3200000000000003" />
          </body>

          

        </body>
      
      
	</worldbody>
	
    
	<actuator>
      

      <motor joint="ankle_y_right" name="ankle_actuator_y" gear="20" />
      <position name="position_servo_y_right" joint="ankle_y_right" kp="10" />
	    <velocity name="velocity_servo_y_right" joint="ankle_y_right" kv="0" />
	</actuator>

    
	<sensor>
      <jointpos joint="ankle_y_right" noise="0.1" />
      <jointvel joint="ankle_y_right" noise="0.1" />
      
	</sensor>
</mujoco>