<mujoco model="initial_humanoid">
  
  <option gravity="0 0 -9.81">
  </option>

  
  <visual>
    <map zfar="30" />
    
    <rgba haze="0.15 0.25 0.35 1" />
    
    
  </visual>

  
  <statistic center="0 0 0.7" />

  
  <asset>
  
    <texture type="skybox" builtin="gradient" rgb1=".3 .5 .7" rgb2="0 0 0" width="32" height="512" />
    
    
    <texture name="body" type="cube" builtin="flat" mark="cross" width="128" height="128" rgb1="0.8 0.6 0.4" rgb2="0.8 0.6 0.4" markrgb="1 1 1" random="0.01" />
    
    <material name="body" texture="body" texuniform="true" rgba="0.8 0.6 .4 1" />
    
     
    <texture name="grid" type="2d" builtin="checker" width="512" height="512" rgb1=".1 .2 .3" rgb2=".2 .3 .4" />
    
    <material name="grid" texture="grid" texrepeat="1 1" texuniform="true" reflectance=".2" />
    
    <mesh name="foot_mesh" vertex="-0.13528 -0.045 0   -0.13528 0.045 0   0.13528 -0.045 0   0.13528 0.045 0  -0.0838736 -0.045 0.06942 -0.0838736 0.045 0.06942" />

    
    <material name="exo_metal" rgba="0.7 0.7 0.7 1" shininess="0.8" specular="0.5" />
    <material name="exo_blue" rgba="0.1 0.3 0.7 1" shininess="0.3" specular="0.3" />
    <material name="exo_straps" rgba="0.3 0.3 0.3 1" shininess="0.1" specular="0.1" />

  </asset>

  
  <default>
    
    <default class="general_geom">
      <motor ctrlrange="-0.5 0.5" ctrllimited="true" />
      
      
      <geom material="body" type="capsule" condim="1" friction="0.99 0.99 0.99" solimp=".9 .99 .003" group="1" />
      
      
      <default class="long_link">
        <geom fromto="0 0 0.1 0 0 0" size="0.025" />
      </default>

    </default>
  </default>

    
	<worldbody>
      
      <geom name="ground" size="0 0 .05" friction="0.99 0.99 0.99" type="plane" material="grid" condim="3" solimp=".9 .99 .003" />
      
      
      <light name="spotlight" mode="targetbodycom" target="foot" diffuse=".8 .8 .8" specular="0.3 0.3 0.3" pos="0 -6 4" cutoff="30" />
    
        
        <body name="foot" pos="0. 0 0" quat="0 0 0 1">
          
          <joint type="hinge" name="rotation_dof" axis="0 1 0" pos="-0.0838736 0 0.06942" />
          <joint type="slide" name="joint_slide_x" axis="1 0 0" pos="-0.0838736 0 0.035" />
          <joint type="slide" name="joint_slide_z" axis="0 0 1" pos="-0.0838736 0 0.035" />

          <site name="front_foot_site" type="cylinder" size="0.075" rgba="0.5 0.5 0.5 0" fromto="-0.13528 0 0.0 -0.13528 0 0.1" />
          <site name="back_foot_site" type="cylinder" size="0.075" rgba="0.5 0.5 0.5 0" fromto="0.13528 0 0.0 0.13528 0 0.1" />
          
          <geom type="mesh" mesh="foot_mesh" name="foot_geom" friction=".99 .99 .99" rgba="0.8 0.6 0.4 1" />
          
          
          <geom name="exo_heel_attachment" type="box" size="0.02 0.025 0.005" pos="-0.1 0 0.005" material="exo_metal" contype="0" conaffinity="0" />
      
            <body name="long_link_body" pos="-0.0838736 0 0.06942">
            
            
              <joint type="hinge" name="ankle_hinge" axis="0 1 0" damping="2.5" pos="0 0 0" />
              <geom name="long_link_geom" class="long_link" solref="0.015 1" solimp=".99 .99 .001" mass="0" fromto="0 0 1.78 0 0 0" />
              <geom name="m_body" type="sphere" size="0.05" mass="77.68" pos="0 0 1.0234999999999999" />

              
              
              <geom name="exo_housing" type="box" size="0.025 0.03 0.04" pos="-0.03 0 0.08" material="exo_blue" contype="0" conaffinity="0" />
                    
              
              <geom name="exo_connecting_rod" type="capsule" fromto="-0.03 0 0.05 -0.03 0 -0.025" size="0.005" material="exo_metal" contype="0" conaffinity="0" />
                    
              
              <geom name="exo_joint_upper" type="sphere" size="0.007" pos="-0.03 0 0.05" material="exo_metal" contype="0" conaffinity="0" />
                    
              
              <geom name="exo_joint_lower" type="sphere" size="0.007" pos="-0.03 0 -0.025" material="exo_metal" contype="0" conaffinity="0" />
              
              
              
              <geom name="exo_calf_strap_left" type="capsule" fromto="-0.03 -0.02 0.08 0.03 -0.02 0.08" size="0.008" material="exo_straps" contype="0" conaffinity="0" />
                    
              
              <geom name="exo_calf_strap_right" type="capsule" fromto="-0.03 0.02 0.08 0.03 0.02 0.08" size="0.008" material="exo_straps" contype="0" conaffinity="0" />
                    
              
              <geom name="exo_calf_strap_top" type="capsule" fromto="0.03 -0.02 0.08 0.03 0.02 0.08" size="0.008" material="exo_straps" contype="0" conaffinity="0" />
            
            </body>

        </body>
	</worldbody>
  
  <contact>
    <pair name="foot_ground_friction" geom1="foot_geom" geom2="ground" solref="0.015 1" solimp="0.99 .99 .003" friction="0.99 0.99 0.99 0.99 0.99" />
    <pair name="longlink_ground_friction" geom1="long_link_geom" geom2="ground" solref="0.015 1" solimp="0.99 .99 .003" friction=".99 .99 .99" />
  </contact>

    
	<actuator>
      <motor joint="ankle_hinge" name="human_ankle_actuator" gear="15" ctrlrange="-10 10" ctrllimited="true" /> 
      <motor joint="ankle_hinge" name="exo_ankle_actuator" gear="10" ctrlrange="-5 5" ctrllimited="true" />
	</actuator>

    
	<sensor>
      <jointpos joint="ankle_hinge" />
      <touch site="front_foot_site" />
      <touch site="back_foot_site" />
	</sensor>

</mujoco>