<mujoco model="initial_humanoid">
  
  <option gravity="0 0 -9.81">
    
    <flag sensornoise="enable" />
  </option>

  
  <visual>
    <map zfar="30" />
    
    <rgba haze="0.15 0.25 0.35 1" />
    
    
  </visual>

  
  <statistic center="0 0 0.7" />

  
  <asset>
    <texture type="skybox" builtin="gradient" rgb1=".3 .5 .7" rgb2="0 0 0" width="32" height="512" />
    <texture name="body" type="cube" builtin="flat" mark="cross" width="128" height="128" rgb1="0.8 0.6 0.4" rgb2="0.8 0.6 0.4" markrgb="1 1 1" random="0.01" />
    <material name="body" texture="body" texuniform="true" rgba="0.8 0.6 .4 1" />
    <texture name="grid" type="2d" builtin="checker" width="512" height="512" rgb1=".1 .2 .3" rgb2=".2 .3 .4" />
    <material name="grid" texture="grid" texrepeat="1 1" texuniform="true" reflectance=".2" />
    <mesh name="tetrahedron" vertex="-0.13528 0 0  0.13528 0 0  0 -0.035 0  0 0.035 0  0.0838736 0 0.178" />
  </asset>

  
  <default>
    <motor ctrlrange="-1 1" ctrllimited="true" />
    <default class="body">

      
      
      <geom type="capsule" mass="10" condim="1" friction="0.7 0.005 0.0001" solimp=".9 .99 .003" solref=".015 1" material="body" group="1" />
      
      
      <default class="shin">
        
        <geom fromto="0 0 0.1 0 0 0" size="0.025" />
      </default>


      
      <default class="foot">
        <geom type="capsule" size=".035" friction="0.9 0 0" solimp=".9 .99 .003" solref=".015 1" mass="2" />
        
        <default class="foot1">
          <geom fromto="-.07 -0.01 0 .14 0.01 0" />
        </default>
        
        <default class="foot2">
          <geom fromto="-.14 -.01 0 .14 .01 0" />
        </default>
       </default>

      
      
      <default class="knee">
        <joint type="hinge" pos="0 0 .02" range="-160 160" />
      </default>
      
      <joint type="hinge" damping=".2" stiffness="1" armature=".01" limited="true" solimplimit="0 .99 .01" />
      <default class="ankle">
        <joint range="-50 50" />
        
        
        <default class="ankle_y">
          <joint pos="0 0 .04" axis="0 1 0" stiffness="6" />
        </default>
        
        
        <default class="ankle_x">
          <joint pos="0 0 .04" stiffness="3" />
        </default>
      </default>  

    </default>
  </default>

    
	<worldbody>
      
      <geom name="ground" size="0 0 .05" type="plane" material="grid" condim="3" friction="0.99 0.99 0.99" solimp=".9 .99 .003" solref=".015 1" />
      
      
      <light name="spotlight" mode="targetbodycom" target="foot" diffuse=".8 .8 .8" specular="0.3 0.3 0.3" pos="0 -6 4" cutoff="30" />
      
      
        
        
        
        <body name="foot" pos="0 0 0">
          
      
          
          <joint name="rotation_dof" type="hinge" axis="0 -1 0" pos="-0.27056 0 0.035" />
          <joint type="slide" name="joint_slide_x" axis="-1 0 0" pos="0.13528 0 0.035" />
          <joint type="slide" name="joint_slide_z" axis="0 0 1" pos="0.13528 0 0.035" />
  
          
            
          
          <geom type="mesh" mesh="tetrahedron" />
          <body name="shin_body" pos="0.0838736 0 0.178">
          
          
          
            <joint type="hinge" name="ankle_hinge" axis="0 -1 0" pos="0 0 0" />
            <geom name="shin_geom" class="shin" fromto="0 0 1.78 0 0 0" mass="77.68" />

          </body>

          

        </body>
      
      
	</worldbody>
	
    
	<actuator>
      
      
      <motor joint="ankle_hinge" name="shin_actuator" gear="60" />
      
      <motor joint="ankle_hinge" name="exo_ankle_actuator_y" gear="40" />
	</actuator>

    
	<sensor>
      <jointpos joint="ankle_hinge" />
      
      
      
	</sensor>
</mujoco>